Performing system checks...

System check identified no issues (0 silenced).
March 04, 2025 - 23:43:04
Django version 4.2.10, using settings 'kanbanproject.settings'
Starting development server at http://127.0.0.1:8000/
Quit the server with CTRL-BREAK.

[04/Mar/2025 23:43:17] "GET / HTTP/1.1" 500 145
[04/Mar/2025 23:43:24] "GET / HTTP/1.1" 500 145
Exception in thread django-main-thread:
Traceback (most recent call last):
  File "C:\Python313\Lib\threading.py", line 1041, in _bootstrap_inner
    self.run()
    ~~~~~~~~^^
  File "C:\Python313\Lib\threading.py", line 992, in run
    self._target(*self._args, **self._kwargs)
    ~~~~~~~~~~~~^^^^^^^^^^^^^^^^^^^^^^^^^^^^^
  File "C:\Users\Daniela Paz\Escritorio\kanbany\venv\Lib\site-packages\django\utils\autoreload.py", line
 64, in wrapper
    fn(*args, **kwargs)
    ~~^^^^^^^^^^^^^^^^^
  File "C:\Users\Daniela Paz\Escritorio\kanbany\venv\Lib\site-packages\django\core\management\commands\runserver.py", line 125, in inner_run
    autoreload.raise_last_exception()
    ~~~~~~~~~~~~~~~~~~~~~~~~~~~~~~~^^
  File "C:\Users\Daniela Paz\Escritorio\kanbany\venv\Lib\site-packages\django\utils\autoreload.py", line
 87, in raise_last_exception
    raise _exception[1]
  File "C:\Users\Daniela Paz\Escritorio\kanbany\venv\Lib\site-packages\django\core\management\__init__.py", line 394, in execute
    autoreload.check_errors(django.setup)()
    ~~~~~~~~~~~~~~~~~~~~~~~~~~~~~~~~~~~~~^^
  File "C:\Users\Daniela Paz\Escritorio\kanbany\venv\Lib\site-packages\django\utils\autoreload.py", line
 64, in wrapper
    fn(*args, **kwargs)
    ~~^^^^^^^^^^^^^^^^^
  File "C:\Users\Daniela Paz\Escritorio\kanbany\venv\Lib\site-packages\django\__init__.py", line 24, in setup
    apps.populate(settings.INSTALLED_APPS)
    ~~~~~~~~~~~~~^^^^^^^^^^^^^^^^^^^^^^^^^
  File "C:\Users\Daniela Paz\Escritorio\kanbany\venv\Lib\site-packages\django\apps\registry.py", line 124, in populate
    app_config.ready()
    ~~~~~~~~~~~~~~~~^^
  File "C:\Users\Daniela Paz\Escritorio\kanbany\venv\Lib\site-packages\django\contrib\admin\apps.py", line 27, in ready
    self.module.autodiscover()
    ~~~~~~~~~~~~~~~~~~~~~~~~^^
  File "C:\Users\Daniela Paz\Escritorio\kanbany\venv\Lib\site-packages\django\contrib\admin\__init__.py", line 50, in autodiscover
    autodiscover_modules("admin", register_to=site)
    ~~~~~~~~~~~~~~~~~~~~^^^^^^^^^^^^^^^^^^^^^^^^^^^
  File "C:\Users\Daniela Paz\Escritorio\kanbany\venv\Lib\site-packages\django\utils\module_loading.py", line 58, in autodiscover_modules
    import_module("%s.%s" % (app_config.name, module_to_search))
    ~~~~~~~~~~~~~^^^^^^^^^^^^^^^^^^^^^^^^^^^^^^^^^^^^^^^^^^^^^^^
  File "C:\Python313\Lib\importlib\__init__.py", line 88, in import_module
    return _bootstrap._gcd_import(name[level:], package, level)
           ~~~~~~~~~~~~~~~~~~~~~~^^^^^^^^^^^^^^^^^^^^^^^^^^^^^^
  File "<frozen importlib._bootstrap>", line 1387, in _gcd_import
  File "<frozen importlib._bootstrap>", line 1360, in _find_and_load
  File "<frozen importlib._bootstrap>", line 1331, in _find_and_load_unlocked
  File "<frozen importlib._bootstrap>", line 935, in _load_unlocked
  File "<frozen importlib._bootstrap_external>", line 1026, in exec_module
  File "<frozen importlib._bootstrap>", line 488, in _call_with_frames_removed
  File "C:\Users\Daniela Paz\Escritorio\kanbany\tasks\admin.py", line 3, in <module>
    from .models import Task, UserProfile
ImportError: cannot import name 'UserProfile' from 'tasks.models' (C:\Users\Daniela Paz\Escritorio\kanbany\tasks\models.py)
